package seawave.day19.exception;

public class Demo3_Exception {

	/**
	 * * A:案例演示
	 * try...catch的方式处理多个异常
	 * JDK7以后处理多个异常的方式及注意事项
	 * 
	 * 安卓,客户端开发,如何处理异常?try{}catch(Exception e){}
	 * ee,服务端开发,一般都是底层开发,从底层向上抛
	 * 
	 * try后面如果跟多个catch,那么小的异常放前面,大的异常放后面,根据多态的原理,如果大的放前面,就会将所有的子类对象接收
	 * 后面的catch就没有意义了
	 */
	public static void main(String[] args) {
		demo1();
		
		demo2(); 
	}

	
	public static void demo2() {
		int a = 10;
		int b = 0;
		int[] arr = {11,22,33,44,55};
		
		//JDK7如何处理多个异常
		try {
			System.out.println(a / b);
			System.out.println(arr[10]);
			
		} catch (ArithmeticException | ArrayIndexOutOfBoundsException e) {
			System.out.println("出错了");
		}
	}

	public static void demo1() {
		int a = 10;
		int b = 0;
		int[] arr = {11,22,33,44,55};
		
		try {
			System.out.println(a / b);
			System.out.println(arr[10]);
			arr = null;
			System.out.println(arr[0]);
		} catch (ArithmeticException e) {
			System.out.println("除数不能为零");
		} catch (ArrayIndexOutOfBoundsException e) {
			System.out.println("索引越界了");
		} catch (Exception e) {				//Exception e = new NullPointerException();
			System.out.println("出错了");
		}
		
		System.out.println("over");
	}

}
